Workbook
Name NGAY_BAT_DAU: '00_Tổng quan'!$D$4

Sheet 00_Tổng quan
A1: LEVART · KẾ HOẠCH TRIỂN KHAI 12 THÁNG — 52 TUẦN · 5 GIAI ĐOẠN · 7 CHU KỲ
A2: ="Nguồn: week_index.md · Business.md · ROLE.md │ Phiên bản 1.0 · lập 22/09/2026 │ Tuần 1 bắt đầu "&TEXT(NGAY_BAT_DAU+0,"dd/mm/yyyy")&" · Tuần 52 kết thúc "&TEXT(NGAY_BAT_DAU+363,"dd/mm/yyyy")&" │ Mục tiêu năm 1: học tập – nghiên cứu – mở rộng từ ý tưởng cốt lõi" -> Nguồn: week_index.md · Business.md · ROLE.md │ Phiên bản 1.0 · lập 22/09/2026 │ Tuần 1 bắt đầu 14/09/2026 · Tuần 52 kết thúc 12/09/2027 │ Mục tiêu năm 1: học tập – nghiên cứu – mở rộng từ ý tưởng cốt lõi
A4: ⚙ Ô VÀNG bên phải là NGÀY BẮT ĐẦU TUẦN 1 (thứ Hai). Sửa một ô này → toàn bộ ngày ở mọi trang tính tự dịch theo. | D4: 46279 | E4: TỔNG ĐẦU MỤC | G4: ĐÃ XONG | I4: ĐANG LÀM | J4: CHƯA BẮT ĐẦU | K4: % HOÀN THÀNH
E5: =COUNT('C1_T01-08'!$A:$A)+COUNT('C2_T09-16'!$A:$A)+COUNT('C3_T17-24'!$A:$A)+COUNT('C4_T25-32'!$A:$A)+COUNT('C5_T33-40'!$A:$A)+COUNT('C6_T41-48'!$A:$A)+COUNT('C7_T49-52'!$A:$A) -> 211 | G5: =COUNTIF('C1_T01-08'!$I:$I,"Xong")+COUNTIF('C2_T09-16'!$I:$I,"Xong")+COUNTIF('C3_T17-24'!$I:$I,"Xong")+COUNTIF('C4_T25-32'!$I:$I,"Xong")+COUNTIF('C5_T33-40'!$I:$I,"Xong")+COUNTIF('C6_T41-48'!$I:$I,"Xong")+COUNTIF('C7_T49-52'!$I:$I,"Xong") -> 0 | I5: =COUNTIF('C1_T01-08'!$I:$I,"Đang làm")+COUNTIF('C2_T09-16'!$I:$I,"Đang làm")+COUNTIF('C3_T17-24'!$I:$I,"Đang làm")+COUNTIF('C4_T25-32'!$I:$I,"Đang làm")+COUNTIF('C5_T33-40'!$I:$I,"Đang làm")+COUNTIF('C6_T41-48'!$I:$I,"Đang làm")+COUNTIF('C7_T49-52'!$I:$I,"Đang làm") -> 0 | J5: =COUNTIF('C1_T01-08'!$I:$I,"Chưa bắt đầu")+COUNTIF('C2_T09-16'!$I:$I,"Chưa bắt đầu")+COUNTIF('C3_T17-24'!$I:$I,"Chưa bắt đầu")+COUNTIF('C4_T25-32'!$I:$I,"Chưa bắt đầu")+COUNTIF('C5_T33-40'!$I:$I,"Chưa bắt đầu")+COUNTIF('C6_T41-48'!$I:$I,"Chưa bắt đầu")+COUNTIF('C7_T49-52'!$I:$I,"Chưa bắt đầu") -> 211 | K5: =IFERROR(($G$5+0)/$E$5,0) -> 0
A7: STT | B7: Giai đoạn / Phase | C7: Đầu mục / Task | D7: Phân việc chi tiết / Subtask | E7: Mục đích / Purpose | F7: Ghế / PIC | G7: Ngày bắt đầu Start Date | H7: Ngày kết thúc End Date | I7: Trạng thái / Status | J7: Tiêu chí hoàn thành / Output | K7: Ghi chú / Note
A8: 1 | B8: QUÝ 1 — GIAI ĐOẠN 1: THẤU CẢM | C8: 1.1 Khởi động dự án (M1) — chốt cách làm việc | D8: [Tuần 01] Tầm nhìn v0 · Phân loại du lịch (nháp) · Xác định vấn đề (giả thuyết) · Tập khách hàng target (dự kiến) · Vai trò từng thành viên · Kịch bản phỏng vấn v0 · Danh sách phỏng vấn · MVP — sơ đồ luồng sử dụng app (as-is) · Lịch họp tuần, thư mục docs/, bãi đỗ ý tưởng · Danh sách 12 người thử nghiệm kín · Biên bản M1 | E8: Ra khỏi tuần với 9 quyết định, ghế có tên, lịch họp đã gửi, và đủ vật liệu để phỏng vấn từ tuần 2. | F8: ALL (ĐP chủ trì) | G8: =NGAY_BAT_DAU+0 -> 46279 | H8: =NGAY_BAT_DAU+6 -> 46285 | I8: =IF(COUNTIF('C1_T01-08'!$I$6:$I$16,"Xong")+COUNTIF('C1_T01-08'!$I$6:$I$16,"Cắt")=11,"Xong",IF(COUNTIF('C1_T01-08'!$I$6:$I$16,"Chưa bắt đầu")=11,"Chưa bắt đầu","Đang làm")) -> Chưa bắt đầu | J8: Biên bản M1 có 9 quyết định · bảng ghế + bảng giờ · tầm nhìn v0 · kịch bản phỏng vấn v0 · danh sách 30–40 tên · sơ đồ luồng as-is · thư mục docs/ có 5 mẫu
A9: 2 | C9: 1.2 Phỏng vấn thử · Số liệu thị trường · Đối thủ | D9: [Tuần 02] 2 phỏng vấn thử · Bảng so sánh 6 app đối thủ · Research số liệu du lịch · Chọn tỉnh mục tiêu → ADR · Danh sách 10 đối tác tỉnh mục tiêu · Khởi tạo bảng số tuần | E9: Kịch bản chạy được trên người thật; thị trường có số có nguồn; đối thủ có ảnh chụp; tỉnh mục tiêu được chốt. | F9: TT · TN · ĐP · VH | G9: =NGAY_BAT_DAU+7 -> 46286 | H9: =NGAY_BAT_DAU+13 -> 46292 | I9: =IF(COUNTIF('C1_T01-08'!$I$18:$I$23,"Xong")+COUNTIF('C1_T01-08'!$I$18:$I$23,"Cắt")=6,"Xong",IF(COUNTIF('C1_T01-08'!$I$18:$I$23,"Chưa bắt đầu")=6,"Chưa bắt đầu","Đang làm")) -> Chưa bắt đầu | J9: Kịch bản v1 · bảng so sánh 6 app có ảnh · tệp số liệu có link · ADR tỉnh mục tiêu · bảng 10 đối tác
A10: 3 | C10: 1.3 Phỏng vấn đợt 1 · Ký thoả thuận đồng sáng lập (M3) | D10: [Tuần 03] ≥ 8 phỏng vấn khách hàng · Ký thoả thuận đồng sáng lập · Mở bảng ghi giờ · Họp Level 10 lần đầu · Gọi 2 đối tác đầu tiên · Marketing trên các nền tảng — 1 trang | E10: ≥ 8 phỏng vấn có tệp; thoả thuận đồng sáng lập ký; họp tuần theo cấu trúc Level 10 lần đầu. | F10: ALL (TT điều phối) | G10: =NGAY_BAT_DAU+14 -> 46293 | H10: =NGAY_BAT_DAU+20 -> 46299 | I10: =IF(COUNTIF('C1_T01-08'!$I$25:$I$30,"Xong")+COUNTIF('C1_T01-08'!$I$25:$I$30,"Cắt")=6,"Xong",IF(COUNTIF('C1_T01-08'!$I$25:$I$30,"Chưa bắt đầu")=6,"Chưa bắt đầu","Đang làm")) -> Chưa bắt đầu | J10: 8 tệp phỏng vấn · thoả thuận đã ký (PDF) · bảng ghi giờ · biên bản Level 10 đầu tiên · ghi chú 2 cuộc gọi đối tác · 1 trang marketing nền tảng
A11: 4 | C11: 1.4 Phỏng vấn ≥ 16 · Nhãn hiệu · Affiliate | D11: [Tuần 04] ≥ 8 phỏng vấn (cộng dồn 16) · Bảng đếm nỗi đau · Tra nhãn hiệu «Levart» · Mua tên miền · 5 câu hỏi luật + đặt hẹn · Gọi 3 đối tác còn lại · Bảng 3 chương trình affiliate · Gom phản hồi về app | E11: Cộng dồn 16 phỏng vấn; biết tên Levart dùng được không; biết affiliate mở cho ai; sẵn câu hỏi cho buổi luật. | F11: ALL · ĐP · VH | G11: =NGAY_BAT_DAU+21 -> 46300 | H11: =NGAY_BAT_DAU+27 -> 46306 | I11: =IF(COUNTIF('C1_T01-08'!$I$32:$I$39,"Xong")+COUNTIF('C1_T01-08'!$I$32:$I$39,"Cắt")=8,"Xong",IF(COUNTIF('C1_T01-08'!$I$32:$I$39,"Chưa bắt đầu")=8,"Chưa bắt đầu","Đang làm")) -> Chưa bắt đầu | J11: 16 tệp phỏng vấn · bảng đếm nỗi đau · kết quả tra nhãn hiệu (có ảnh) · tên miền đã mua · 5 câu hỏi luật + lịch hẹn · bảng 3 chương trình affiliate
A12: 5 | C12: 1.5 Phỏng vấn ≥ 24 · Buổi hỏi luật | D12: [Tuần 05] ≥ 8 phỏng vấn (cộng dồn 24) · Phân tích chéo sơ bộ · Buổi 45' với người hiểu luật · Danh mục pháp lý v1 · Tổng hợp 5 cuộc gọi đối tác · Phân loại du lịch v1 | E12: Cộng dồn 24 phỏng vấn; có câu trả lời thật cho 5 câu luật; biết ai đau nhất; biết đối tác nào sẵn lòng thử. | F12: ALL · ĐP · VH · TN | G12: =NGAY_BAT_DAU+28 -> 46307 | H12: =NGAY_BAT_DAU+34 -> 46313 | I12: =IF(COUNTIF('C1_T01-08'!$I$41:$I$46,"Xong")+COUNTIF('C1_T01-08'!$I$41:$I$46,"Cắt")=6,"Xong",IF(COUNTIF('C1_T01-08'!$I$41:$I$46,"Chưa bắt đầu")=6,"Chưa bắt đầu","Đang làm")) -> Chưa bắt đầu | J12: 24 tệp phỏng vấn · biên bản buổi luật · danh mục pháp lý v1 · bảng đối tác có thể có · phân loại du lịch v1
A13: 6 | C13: 1.6 Phỏng vấn ≥ 30 · Rủi ro · Tình huống ngoại lệ | D13: [Tuần 06] ≥ 6 phỏng vấn (cộng dồn 30) · Pre-mortem + sổ rủi ro v1 · Bảng tình huống ngoại lệ của tỉnh · Sơ đồ luồng to-be nháp · Chuẩn bị buổi tổng hợp T7 | E13: Đủ 30 phỏng vấn; sổ rủi ro v1 có người theo dõi; bảng tình huống của tỉnh; luồng to-be nháp. | F13: ALL · ĐP · VH · SP | G13: =NGAY_BAT_DAU+35 -> 46314 | H13: =NGAY_BAT_DAU+41 -> 46320 | I13: =IF(COUNTIF('C1_T01-08'!$I$48:$I$52,"Xong")+COUNTIF('C1_T01-08'!$I$48:$I$52,"Cắt")=5,"Xong",IF(COUNTIF('C1_T01-08'!$I$48:$I$52,"Chưa bắt đầu")=5,"Chưa bắt đầu","Đang làm")) -> Chưa bắt đầu | J13: 30 tệp phỏng vấn · sổ rủi ro v1 (≥ 12 dòng, top 5 có người) · bảng khẩn cấp tỉnh mục tiêu · sơ đồ luồng to-be nháp
A14: 7 | C14: 1.7 NGUỘI · Kết chu kỳ 1 (M7) — phân tích 30 phỏng vấn | D14: [Tuần 07] Buổi tổng hợp 3 giờ · Kết 3 cược chu kỳ 1 · Gạch giả thuyết G1–G8 · Bù giờ | E14: Biến 30 tệp thành persona v1, top 3 nỗi đau có số, và câu trả lời bằng số cho «khách có thật sự cần không». | F14: ALL (TT chủ trì) | G14: =NGAY_BAT_DAU+42 -> 46321 | H14: =NGAY_BAT_DAU+48 -> 46327 | I14: =IF(COUNTIF('C1_T01-08'!$I$54:$I$57,"Xong")+COUNTIF('C1_T01-08'!$I$54:$I$57,"Cắt")=4,"Xong",IF(COUNTIF('C1_T01-08'!$I$54:$I$57,"Chưa bắt đầu")=4,"Chưa bắt đầu","Đang làm")) -> Chưa bắt đầu | J14: persona v1 · top3-noi-dau.md có số + ảnh bảng · 3 thẻ cược C1 đã điền kết quả · biên bản kết C1 · bảng G1–G8 cập nhật
A15: 8 | C15: 1.8 NGUỘI · Business.md 0.2 · Kịch bản lần 2 · Bàn cược C2 | D15: [Tuần 08] Business.md 0.2 · Kịch bản phỏng vấn lần 2 (phỏng vấn giải pháp, 20') · Bàn cược chu kỳ 2 (T9–T14) · Chính sách quyền riêng tư (nháp) · Danh mục kỹ thuật tối thiểu cho cohort · Trang tĩnh (tên miền) | E15: Tài liệu nền phản ánh bằng chứng; sẵn kịch bản lần 2; ba cược cho chu kỳ 2; chính sách riêng tư và trang tĩnh sẵn trước khi người ngoài dùng app. | F15: TN · TT · ĐP · SP | G15: =NGAY_BAT_DAU+49 -> 46328 | H15: =NGAY_BAT_DAU+55 -> 46334 | I15: =IF(COUNTIF('C1_T01-08'!$I$59:$I$64,"Xong")+COUNTIF('C1_T01-08'!$I$59:$I$64,"Cắt")=6,"Xong",IF(COUNTIF('C1_T01-08'!$I$59:$I$64,"Chưa bắt đầu")=6,"Chưa bắt đầu","Đang làm")) -> Chưa bắt đầu | J15: Business.md 0.2 · kịch bản phỏng vấn lần 2 + 3 thẻ giá · 3 thẻ cược C2 · chính sách riêng tư nháp · trang tĩnh
A16: ="🎯 MỐC REVIEW CHU KỲ 1 (R1): Kết chu kỳ 1 & phân tích 30 phỏng vấn │ 📅 Thời gian: "&TEXT(NGAY_BAT_DAU+0,"dd/mm/yyyy")&" – "&TEXT(NGAY_BAT_DAU+55,"dd/mm/yyyy")&" (T01–T08) │ 👤 PIC: ALL (TT chủ trì buổi tổng hợp 3 giờ) │ 🎯 Mục đích: Biến 30 tệp phỏng vấn thành persona v1 + top 3 nỗi đau có số; kết 3 cược C1; gạch giả thuyết G1–G8 │ 📋"&" Output: Persona v1 · top 3 nỗi đau có % · biên bản kết C1 · Business.md 0.2 · 3 thẻ cược C2 │ 📝 Ghi chú: Tuần nguội T7–T8 — không xếp việc mới │ ⏳ Trạng thái: Chưa bắt đầu" -> 🎯 MỐC REVIEW CHU KỲ 1 (R1): Kết chu kỳ 1 & phân tích 30 phỏng vấn │ 📅 Thời gian: 14/09/2026 – 08/11/2026 (T01–T08) │ 👤 PIC: ALL (TT chủ trì buổi tổng hợp 3 giờ) │ 🎯 Mục đích: Biến 30 tệp phỏng vấn thành persona v1 + top 3 nỗi đau có số; kết 3 cược C1; gạch giả thuyết G1–G8 │ 📋 Output: Persona v1 · top 3 nỗi đau có % · biên bản kết C1 · Business.md 0.2 · 3 thẻ cược C2 │ 📝 Ghi chú: Tuần nguội T7–T8 — không xếp việc mới │ ⏳ Trạng thái: Chưa bắt đầu
A17: 9 | B17: QUÝ 1 — GIAI ĐOẠN 1: THẤU CẢM | C17: 1.9 Thử nghiệm kín 12 người · Phỏng vấn lần 2 | D17: [Tuần 09] Thử nghiệm kín 12 người · Phễu đo hoạt động · 5 phỏng vấn lần 2 · 3 nội dung ngắn đầu tiên · Ưu đãi đối tác — 1 trang · Công khai trang tĩnh | E17: Đồng hồ 14 ngày của Google Play bắt đầu; phễu có số thật đầu tiên; 5 phỏng vấn lần 2; 3 nội dung đầu. | F17: SP · TT · VH · ĐP | G17: =NGAY_BAT_DAU+56 -> 46335 | H17: =NGAY_BAT_DAU+62 -> 46341 | I17: =IF(COUNTIF('C2_T09-16'!$I$6:$I$11,"Xong")+COUNTIF('C2_T09-16'!$I$6:$I$11,"Cắt")=6,"Xong",IF(COUNTIF('C2_T09-16'!$I$6:$I$11,"Chưa bắt đầu")=6,"Chưa bắt đầu","Đang làm")) -> Chưa bắt đầu | J17: 12 người đã cài (có ngày) · bảng số có cột kích hoạt · 5 tệp phỏng vấn lần 2 · 3 link nội dung · 3 đối tác xác nhận ưu đãi · trang tĩnh công khai
A18: 10 | C18: 1.10 Cohort 30 người · Phân tích lần 2 · Slogan | D18: [Tuần 10] Mời cohort lên 30 người · 5 phỏng vấn lần 2 còn lại + phân tích · Thử 3 slogan với 20 người ngoài nhóm · Chạy ưu đãi đối tác · Theo dõi lỗi cohort · 3 nội dung tiếp theo | E18: 30 người dùng thật có nguồn; kết quả 10 phỏng vấn lần 2; slogan v1 chọn bằng người ngoài. | F18: TT · TN · VH · SP | G18: =NGAY_BAT_DAU+63 -> 46342 | H18: =NGAY_BAT_DAU+69 -> 46348 | I18: =IF(COUNTIF('C2_T09-16'!$I$13:$I$18,"Xong")+COUNTIF('C2_T09-16'!$I$13:$I$18,"Cắt")=6,"Xong",IF(COUNTIF('C2_T09-16'!$I$13:$I$18,"Chưa bắt đầu")=6,"Chưa bắt đầu","Đang làm")) -> Chưa bắt đầu | J18: Bảng cohort 30 dòng có nguồn · phong-van-lan-2-ket-qua.md · ADR slogan v1 · bảng theo dõi ưu đãi · bảng lỗi
A19: 11 | C19: 1.11 Đo kích hoạt & quay lại · Dòng tiền v0 | D19: [Tuần 11] Bảng số T11 · Dòng tiền v0 · 4 nội dung còn lại + bảng nội dung · Mở rộng bảng đối tác có thể có · Chuẩn bị khảo sát «rất thất vọng» | E19: Bảng số có 4 chỉ số thật; biết chi phí cố định 12 tháng; 10 nội dung có số; sẵn khảo sát. | F19: ĐP · TT · VH · SP | G19: =NGAY_BAT_DAU+70 -> 46349 | H19: =NGAY_BAT_DAU+76 -> 46355 | I19: =IF(COUNTIF('C2_T09-16'!$I$20:$I$24,"Xong")+COUNTIF('C2_T09-16'!$I$20:$I$24,"Cắt")=5,"Xong",IF(COUNTIF('C2_T09-16'!$I$20:$I$24,"Chưa bắt đầu")=5,"Chưa bắt đầu","Đang làm")) -> Chưa bắt đầu | J19: Bảng số T11 có 4 chỉ số · dòng tiền v0 + đoạn giả định · bảng 10 nội dung có số · bảng đối tác có thể có ≥ 12 dòng · form khảo sát + danh sách người nhận
A20: 12 | C20: 1.12 CỔNG QUÝ 1 (M12) — tiếp / xoay / dừng | D20: [Tuần 12] Khảo sát Sean Ellis · Họp cổng 2 giờ · Điều kiện phát hành production · Cập nhật giai đoạn trong Business.md | E20: Quyết định tiếp / xoay / dừng bằng bảng tiêu chí đã viết trước; chốt Rocks Q2; đủ điều kiện xin phát hành. | F20: ALL (TN quyết cuối) | G20: =NGAY_BAT_DAU+77 -> 46356 | H20: =NGAY_BAT_DAU+83 -> 46362 | I20: =IF(COUNTIF('C2_T09-16'!$I$26:$I$29,"Xong")+COUNTIF('C2_T09-16'!$I$26:$I$29,"Cắt")=4,"Xong",IF(COUNTIF('C2_T09-16'!$I$26:$I$29,"Chưa bắt đầu")=4,"Chưa bắt đầu","Đang làm")) -> Chưa bắt đầu | J20: Kết quả khảo sát «rất thất vọng» + n · biên bản cổng Q1 · ADR tiếp/xoay/dừng · 3 Rocks Q2 · đơn xin quyền phát hành (hoặc danh sách còn thiếu có hạn)
A21: ="🚩 CỔNG QUÝ 1 (G1): Giai đoạn 1 THẤU CẢM → Giai đoạn 2 BÁM DÍNH │ 📅 Thời gian: "&TEXT(NGAY_BAT_DAU+77,"dd/mm/yyyy")&" – "&TEXT(NGAY_BAT_DAU+83,"dd/mm/yyyy")&" (T12–T12) │ 👤 PIC: ALL (TN quyết cuối) │ 🎯 Mục đích: Quyết định tiếp / xoay / dừng bằng bảng tiêu chí viết trước, không quyết bằng cảm tính │ 📋 Output: Tiêu chí: ≥ 30 phỏng"&" vấn có bài học · ≥ 60% tự nêu cùng một nỗi đau · persona v1 · ≥ 3 đối tác đồng ý thử · cohort 30 người có số kích hoạt → Biên bản cổng + ADR + 3 Rocks Q2 │ 📝 Ghi chú: Đồng thời "&"kiểm đủ điều kiện xin quyền phát hành production │ ⏳ Trạng thái: Chưa bắt đầu" -> 🚩 CỔNG QUÝ 1 (G1): Giai đoạn 1 THẤU CẢM → Giai đoạn 2 BÁM DÍNH │ 📅 Thời gian: 30/11/2026 – 06/12/2026 (T12–T12) │ 👤 PIC: ALL (TN quyết cuối) │ 🎯 Mục đích: Quyết định tiếp / xoay / dừng bằng bảng tiêu chí viết trước, không quyết bằng cảm tính │ 📋 Output: Tiêu chí: ≥ 30 phỏng vấn có bài học · ≥ 60% tự nêu cùng một nỗi đau · persona v1 · ≥ 3 đối tác đồng ý thử · cohort 30 người có số kích hoạt → Biên bản cổng + ADR + 3 Rocks Q2 │ 📝 Ghi chú: Đồng thời kiểm đủ điều kiện xin quyền phát hành production │ ⏳ Trạng thái: Chưa bắt đầu
A22: 13 | B22: QUÝ 2 — GIAI ĐOẠN 2: BÁM DÍNH | C22: 2.1 Phỏng vấn người bỏ · Phân loại v2 · Brief con dấu | D22: [Tuần 13] 5 phỏng vấn người bỏ (churn) · Phân loại du lịch v2 · Brief tài sản đặc trưng (con dấu 34 tỉnh) · Cập nhật danh mục pháp lý + nộp nhãn hiệu · Thu sự cố thật của cohort | E22: Biết vì sao người ta bỏ; chốt nhãn phân loại; khởi động tài sản hình ảnh; nộp nhãn hiệu. | F22: TT · TN · ĐP · VH | G22: =NGAY_BAT_DAU+84 -> 46363 | H22: =NGAY_BAT_DAU+90 -> 46369 | I22: =IF(COUNTIF('C2_T09-16'!$I$31:$I$35,"Xong")+COUNTIF('C2_T09-16'!$I$31:$I$35,"Cắt")=5,"Xong",IF(COUNTIF('C2_T09-16'!$I$31:$I$35,"Chưa bắt đầu")=5,"Chưa bắt đầu","Đang làm")) -> Chưa bắt đầu | J22: 5 tệp phỏng vấn churn + churn-C2.md · phân loại v2 + ADR · brief tài sản đặc trưng + người nhận · đơn nhãn hiệu có số nhận · ≥ 5 sự cố thật
A23: 14 | C23: 2.2 Kết chu kỳ 2 | D23: [Tuần 14] Kết 3 cược C2 · Danh mục ≤ 3 tính năng cho C3 · Dòng tiền v1 · Lịch tuần đệm T15–T16 | E23: Kết 3 cược bằng số; chọn ≤ 3 tính năng đáng xây và vì sao; chi phí/người v0. | F23: ALL · SP · TT · ĐP | G23: =NGAY_BAT_DAU+91 -> 46370 | H23: =NGAY_BAT_DAU+97 -> 46376 | I23: =IF(COUNTIF('C2_T09-16'!$I$37:$I$40,"Xong")+COUNTIF('C2_T09-16'!$I$37:$I$40,"Cắt")=4,"Xong",IF(COUNTIF('C2_T09-16'!$I$37:$I$40,"Chưa bắt đầu")=4,"Chưa bắt đầu","Đang làm")) -> Chưa bắt đầu | J23: Biên bản kết C2 · danh mục ≤ 3 tính năng C3 có cột «vì sao» · dòng tiền v1 · lịch tuần đệm
A24: 15 | C24: 2.3 NGUỘI · Business.md 0.3 · Chọn 2 kênh (Bullseye) | D24: [Tuần 15] Business.md 0.3 · Bullseye — chọn 2 kênh · Kiểm 3 việc bắt buộc + kế hoạch phát hành · Cập nhật so sánh đối thủ | E24: Tài liệu và quyết định kênh; kiểm điều kiện phát hành. (Trùng kỳ thi học kỳ 1 — tải nhẹ.) | F24: TN · TT · ĐP · SP | G24: =NGAY_BAT_DAU+98 -> 46377 | H24: =NGAY_BAT_DAU+104 -> 46383 | I24: =IF(COUNTIF('C2_T09-16'!$I$42:$I$45,"Xong")+COUNTIF('C2_T09-16'!$I$42:$I$45,"Cắt")=4,"Xong",IF(COUNTIF('C2_T09-16'!$I$42:$I$45,"Chưa bắt đầu")=4,"Chưa bắt đầu","Đang làm")) -> Chưa bắt đầu | J24: Business.md 0.3 · ADR chọn 2 kênh · kế hoạch phát hành 1 trang · ghi chú cập nhật đối thủ
A25: 16 | C25: 2.4 NGUỘI · Bàn cược C3 · Con dấu v1 | D25: [Tuần 16] Bàn cược C3 (T17–T22) · Nhận thiết kế con dấu v1 · Kế hoạch chiến dịch trường 1 · Lịch trực lỗi Tết Dương | E25: Ba cược cho chu kỳ 3; bộ hình con dấu v1; kế hoạch chiến dịch trường. | F25: ALL · TN · TT · SP | G25: =NGAY_BAT_DAU+105 -> 46384 | H25: =NGAY_BAT_DAU+111 -> 46390 | I25: =IF(COUNTIF('C2_T09-16'!$I$47:$I$50,"Xong")+COUNTIF('C2_T09-16'!$I$47:$I$50,"Cắt")=4,"Xong",IF(COUNTIF('C2_T09-16'!$I$47:$I$50,"Chưa bắt đầu")=4,"Chưa bắt đầu","Đang làm")) -> Chưa bắt đầu | J25: 3 thẻ cược C3 · bộ hình con dấu v1 · kế hoạch chiến dịch trường 1 · lịch trực lỗi Tết Dương
A26: ="🎯 MỐC REVIEW CHU KỲ 2 (R2): Kết chu kỳ 2 & chọn kênh │ 📅 Thời gian: "&TEXT(NGAY_BAT_DAU+56,"dd/mm/yyyy")&" – "&TEXT(NGAY_BAT_DAU+111,"dd/mm/yyyy")&" (T09–T16) │ 👤 PIC: ALL (ĐP chủ trì) │ 🎯 Mục đích: Kết 3 cược C2 bằng số; chọn ≤ 3 tính năng đáng xây; chọn 2 kênh (Bullseye); chuẩn bị phát hành │ 📋 Output: Biên bản kết C2"&" · danh mục ≤ 3 tính năng có cột «vì sao» · dòng tiền v1 · ADR kênh · bộ hình con dấu v1 · 3 thẻ cược C3 │ 📝 Ghi chú: T15–T16 trùng kỳ thi học kỳ 1 và Tết Dương — tải nhẹ │ ⏳ T"&"rạng thái: Chưa bắt đầu" -> 🎯 MỐC REVIEW CHU KỲ 2 (R2): Kết chu kỳ 2 & chọn kênh │ 📅 Thời gian: 09/11/2026 – 03/01/2027 (T09–T16) │ 👤 PIC: ALL (ĐP chủ trì) │ 🎯 Mục đích: Kết 3 cược C2 bằng số; chọn ≤ 3 tính năng đáng xây; chọn 2 kênh (Bullseye); chuẩn bị phát hành │ 📋 Output: Biên bản kết C2 · danh mục ≤ 3 tính năng có cột «vì sao» · dòng tiền v1 · ADR kênh · bộ hình con dấu v1 · 3 thẻ cược C3 │ 📝 Ghi chú: T15–T16 trùng kỳ thi học kỳ 1 và Tết Dương — tải nhẹ │ ⏳ Trạng thái: Chưa bắt đầu
A27: 17 | B27: QUÝ 2 — GIAI ĐOẠN 2: BÁM DÍNH | C27: 2.5 Phát hành production · ASO · Chiến dịch trường 1 | D27: [Tuần 17] Phát hành production · Trang cửa hàng (ASO cơ bản) · Chiến dịch trường tuần 1 · Chuẩn bị đối tác mùa xuân · Thêm cột quay lại 30 ngày | E27: App công khai; trang cửa hàng mang con dấu; +30 người lạ. | F27: SP · TT · TN · VH · ĐP | G27: =NGAY_BAT_DAU+112 -> 46391 | H27: =NGAY_BAT_DAU+118 -> 46397 | I27: =IF(COUNTIF('C3_T17-24'!$I$6:$I$10,"Xong")+COUNTIF('C3_T17-24'!$I$6:$I$10,"Cắt")=5,"Xong",IF(COUNTIF('C3_T17-24'!$I$6:$I$10,"Chưa bắt đầu")=5,"Chưa bắt đầu","Đang làm")) -> Chưa bắt đầu | J27: App công khai · trang cửa hàng cập nhật + ảnh chụp · bảng cohort +30 có nguồn · 3 đối tác xác nhận mùa xuân · số quay lại 30 ngày đầu tiên
A28: 18 | C28: 2.6 Mở rộng cohort · Nội dung 2 kênh · Xác minh hotline | D28: [Tuần 18] Nội dung 3 bài/tuần × 2 kênh · Tính năng 1 · Gọi thử từng số hotline · Chiến dịch trường tuần 2 | E28: +30 người; số cài theo kênh; biết hotline nào thật; tính năng 1 ra mắt. | F28: TT · SP · VH | G28: =NGAY_BAT_DAU+119 -> 46398 | H28: =NGAY_BAT_DAU+125 -> 46404 | I28: =IF(COUNTIF('C3_T17-24'!$I$12:$I$15,"Xong")+COUNTIF('C3_T17-24'!$I$12:$I$15,"Cắt")=4,"Xong",IF(COUNTIF('C3_T17-24'!$I$12:$I$15,"Chưa bắt đầu")=4,"Chưa bắt đầu","Đang làm")) -> Chưa bắt đầu | J28: Bảng nội dung tuần + K sơ bộ · tính năng 1 ra mắt có số đo · bảng hotline có cột «đã gọi ngày» · +60 người cộng dồn
A29: 19 | C29: 2.7 Dòng tiền v2 · Kinh tế đơn vị · Giá hộ chiếu in | D29: [Tuần 19] Dòng tiền v2 + kinh tế đơn vị · Giá hộ chiếu in · Tính năng 2 · Nội dung + chiến dịch tuần 3 | E29: Biết chi phí mỗi người dùng/tháng, kênh CAC thấp nhất, và giá hộ chiếu in dự kiến. | F29: ĐP · TN · SP · TT | G29: =NGAY_BAT_DAU+126 -> 46405 | H29: =NGAY_BAT_DAU+132 -> 46411 | I29: =IF(COUNTIF('C3_T17-24'!$I$17:$I$20,"Xong")+COUNTIF('C3_T17-24'!$I$17:$I$20,"Cắt")=4,"Xong",IF(COUNTIF('C3_T17-24'!$I$17:$I$20,"Chưa bắt đầu")=4,"Chưa bắt đầu","Đang làm")) -> Chưa bắt đầu | J29: Sheet dòng tiền v2 + 1 trang đọc kết quả · bảng giá vốn 3 nhà in + 3 thẻ giá · tính năng 2 ra mắt
A30: 20 | C30: 2.8 Chuẩn bị Tết · Khảo sát Sean Ellis đợt 2 | D30: [Tuần 20] Nội dung Tết · Khảo sát Sean Ellis đợt 2 · Tính năng 3 hoặc sửa lỗi · Đối tác dịp Tết · Kế hoạch Tết cho nhóm | E30: Nội dung Tết lên lịch; khảo sát đợt 2; kế hoạch trực Tết. | F30: TT · ĐP · SP · VH | G30: =NGAY_BAT_DAU+133 -> 46412 | H30: =NGAY_BAT_DAU+139 -> 46418 | I30: =IF(COUNTIF('C3_T17-24'!$I$22:$I$26,"Xong")+COUNTIF('C3_T17-24'!$I$22:$I$26,"Cắt")=5,"Xong",IF(COUNTIF('C3_T17-24'!$I$22:$I$26,"Chưa bắt đầu")=5,"Chưa bắt đầu","Đang làm")) -> Chưa bắt đầu | J30: Lịch đăng nội dung Tết + người đăng · kết quả khảo sát đợt 2 + so sánh đợt 1 · tính năng 3 · kế hoạch Tết cho nhóm
A31: 21 | C31: 2.9 TẾT (tuần đệm) — theo dõi số | D31: [Tuần 21] Gom số hằng ngày · Trực lỗi chặn · Đăng theo lịch · Nghỉ | E31: Giữ nhịp tối thiểu, không xếp cược nặng. Tết Nguyên đán 2027 (06/02). | F31: ĐP · SP · TT | G31: =NGAY_BAT_DAU+140 -> 46419 | H31: =NGAY_BAT_DAU+146 -> 46425 | I31: =IF(COUNTIF('C3_T17-24'!$I$28:$I$31,"Xong")+COUNTIF('C3_T17-24'!$I$28:$I$31,"Cắt")=4,"Xong",IF(COUNTIF('C3_T17-24'!$I$28:$I$31,"Chưa bắt đầu")=4,"Chưa bắt đầu","Đang làm")) -> Chưa bắt đầu | J31: Sheet số hằng ngày · bảng lỗi · link nội dung Tết
A32: 22 | C32: 2.10 TẾT (tuần đệm) — nghỉ | D32: [Tuần 22] Tiếp tục gom số + trực lỗi | E32: Nghỉ Tết. Không họp hoặc họp 30'. | F32: ĐP · SP | G32: =NGAY_BAT_DAU+147 -> 46426 | H32: =NGAY_BAT_DAU+153 -> 46432 | I32: =IF(COUNTIF('C3_T17-24'!$I$33:$I$33,"Xong")+COUNTIF('C3_T17-24'!$I$33:$I$33,"Cắt")=1,"Xong",IF(COUNTIF('C3_T17-24'!$I$33:$I$33,"Chưa bắt đầu")=1,"Chưa bắt đầu","Đang làm")) -> Chưa bắt đầu | J32: Ghi chú hành vi dịp Tết
A33: 23 | C33: 2.11 NGUỘI · Kết chu kỳ 3 · Phân tích Tết · Phỏng vấn ở lại/bỏ | D33: [Tuần 23] Kết chu kỳ 3 · Tính quay lại 30 ngày · Phân tích hành vi Tết · 5 + 5 phỏng vấn (ở lại / bỏ) · Business.md 0.4 | E33: Kết C3; quay lại 30 ngày thật; biết điều gì giữ người. | F33: ALL · ĐP · TT · TN | G33: =NGAY_BAT_DAU+154 -> 46433 | H33: =NGAY_BAT_DAU+160 -> 46439 | I33: =IF(COUNTIF('C3_T17-24'!$I$35:$I$39,"Xong")+COUNTIF('C3_T17-24'!$I$35:$I$39,"Cắt")=5,"Xong",IF(COUNTIF('C3_T17-24'!$I$35:$I$39,"Chưa bắt đầu")=5,"Chưa bắt đầu","Đang làm")) -> Chưa bắt đầu | J33: Biên bản kết C3 · bảng quay lại 30 ngày (tách theo kênh và quen/lạ) · 5 dòng học được từ Tết · 10 tệp phỏng vấn + dieu-giu-nguoi.md · Business.md 0.4
A34: 24 | C34: 2.12 CỔNG QUÝ 2 · ADR pháp nhân · Bàn cược C4 | D34: [Tuần 24] Họp cổng 2 giờ · ADR pháp nhân · Chốt Rocks Q3 · Bàn cược C4 (T25–T30) | E34: Qua cổng hay không; quyết định pháp nhân; Rocks Q3; ba cược C4. | F34: ALL (TN · ĐP quyết cuối) | G34: =NGAY_BAT_DAU+161 -> 46440 | H34: =NGAY_BAT_DAU+167 -> 46446 | I34: =IF(COUNTIF('C3_T17-24'!$I$41:$I$44,"Xong")+COUNTIF('C3_T17-24'!$I$41:$I$44,"Cắt")=4,"Xong",IF(COUNTIF('C3_T17-24'!$I$41:$I$44,"Chưa bắt đầu")=4,"Chưa bắt đầu","Đang làm")) -> Chưa bắt đầu | J34: Biên bản cổng Q2 + ADR · ADR pháp nhân có chữ ký · 3 Rocks Q3 · 3 thẻ cược C4
A35: ="🎯 MỐC REVIEW CHU KỲ 3 (R3): Kết chu kỳ 3 & phân tích Tết │ 📅 Thời gian: "&TEXT(NGAY_BAT_DAU+112,"dd/mm/yyyy")&" – "&TEXT(NGAY_BAT_DAU+160,"dd/mm/yyyy")&" (T17–T23) │ 👤 PIC: ALL (ĐP chủ trì) │ 🎯 Mục đích: Kết C3 (dời sang T23 vì Tết); đo quay lại 30 ngày thật; phỏng vấn người ở lại và người bỏ │ 📋 Output: Biên bản kết C3 · bả"&"ng quay lại 30 ngày tách theo kênh và quen/lạ · dieu-giu-nguoi.md · Business.md 0.4 │ 📝 Ghi chú: T21–T22 nghỉ Tết Nguyên đán 2027 (06/02) — không họp hoặc họp 30' │ ⏳ Trạng thá"&"i: Chưa bắt đầu" -> 🎯 MỐC REVIEW CHU KỲ 3 (R3): Kết chu kỳ 3 & phân tích Tết │ 📅 Thời gian: 04/01/2027 – 21/02/2027 (T17–T23) │ 👤 PIC: ALL (ĐP chủ trì) │ 🎯 Mục đích: Kết C3 (dời sang T23 vì Tết); đo quay lại 30 ngày thật; phỏng vấn người ở lại và người bỏ │ 📋 Output: Biên bản kết C3 · bảng quay lại 30 ngày tách theo kênh và quen/lạ · dieu-giu-nguoi.md · Business.md 0.4 │ 📝 Ghi chú: T21–T22 nghỉ Tết Nguyên đán 2027 (06/02) — không họp hoặc họp 30' │ ⏳ Trạng thái: Chưa bắt đầu
A36: ="🚩 CỔNG QUÝ 2 (G2): Giai đoạn 2 BÁM DÍNH → Giai đoạn 3 LAN TRUYỀN │ 📅 Thời gian: "&TEXT(NGAY_BAT_DAU+161,"dd/mm/yyyy")&" – "&TEXT(NGAY_BAT_DAU+167,"dd/mm/yyyy")&" (T24–T24) │ 👤 PIC: ALL (TN · ĐP quyết cuối) │ 🎯 Mục đích: Quyết định tiếp / xoay / dừng; và quyết định CỬA MỘT CHIỀU: lập doanh nghiệp trong Q3 │ 📋 Output: Tiêu chí: ≥ 40% "&"«rất thất vọng» (đợt 2) · quay lại 30 ngày ≥ ngưỡng đặt ở T12 · ≥ 100 người hoạt động 1 trường · biết chi phí/người → Biên bản cổng + ADR pháp nhân có chữ ký + Rocks Q3 + 3 thẻ cượ"&"c C4 │ 📝 Ghi chú: Lập DN vì chuẩn bị bật dòng thu (affiliate T28, hộ chiếu in T33) và ngưỡng mạng xã hội │ ⏳ Trạng thái: Chưa bắt đầu" -> 🚩 CỔNG QUÝ 2 (G2): Giai đoạn 2 BÁM DÍNH → Giai đoạn 3 LAN TRUYỀN │ 📅 Thời gian: 22/02/2027 – 28/02/2027 (T24–T24) │ 👤 PIC: ALL (TN · ĐP quyết cuối) │ 🎯 Mục đích: Quyết định tiếp / xoay / dừng; và quyết định CỬA MỘT CHIỀU: lập doanh nghiệp trong Q3 │ 📋 Output: Tiêu chí: ≥ 40% «rất thất vọng» (đợt 2) · quay lại 30 ngày ≥ ngưỡng đặt ở T12 · ≥ 100 người hoạt động 1 trường · biết chi phí/người → Biên bản cổng + ADR pháp nhân có chữ ký + Rocks Q3 + 3 thẻ cược C4 │ 📝 Ghi chú: Lập DN vì chuẩn bị bật dòng thu (affiliate T28, hộ chiếu in T33) và ngưỡng mạng xã hội │ ⏳ Trạng thái: Chưa bắt đầu
A37: 25 | B37: QUÝ 3 — GIAI ĐOẠN 3: LAN TRUYỀN & CHUẨN BỊ DOANH THU | C37: 3.1 Đặt trước hộ chiếu in · Hồ sơ DN · Mời chuyến đi chung | D37: [Tuần 25] Trang đặt trước hộ chiếu in · Hồ sơ doanh nghiệp · Mời chuyến đi chung thủ công · Cơ chế chia sẻ con dấu / mời bạn | E37: Trang đặt trước sống; hồ sơ DN đủ; nhóm đi chung đủ người; cơ chế mời có. | F37: TT · TN · ĐP · VH · SP | G37: =NGAY_BAT_DAU+168 -> 46447 | H37: =NGAY_BAT_DAU+174 -> 46453 | I37: =IF(COUNTIF('C4_T25-32'!$I$6:$I$9,"Xong")+COUNTIF('C4_T25-32'!$I$6:$I$9,"Cắt")=4,"Xong",IF(COUNTIF('C4_T25-32'!$I$6:$I$9,"Chưa bắt đầu")=4,"Chưa bắt đầu","Đang làm")) -> Chưa bắt đầu | J37: Trang đặt trước live + bảng số theo ngày · bộ hồ sơ DN đã rà · 6–8 người xác nhận đi chung + ngày chốt · cơ chế chia sẻ con dấu ra mắt
A38: 26 | C38: 3.2 Nộp hồ sơ DN · Chọn kế toán · 10 creator | D38: [Tuần 26] Nộp hồ sơ doanh nghiệp · 3 báo giá kế toán dịch vụ · Chuẩn bị affiliate đứng tên DN · Đo hệ số mời K · Danh sách 10 creator | E38: Hồ sơ nộp; kế toán chọn; K sơ bộ; 10 creator có liên hệ. | F38: ĐP · VH · TT · TN | G38: =NGAY_BAT_DAU+175 -> 46454 | H38: =NGAY_BAT_DAU+181 -> 46460 | I38: =IF(COUNTIF('C4_T25-32'!$I$11:$I$15,"Xong")+COUNTIF('C4_T25-32'!$I$11:$I$15,"Cắt")=5,"Xong",IF(COUNTIF('C4_T25-32'!$I$11:$I$15,"Chưa bắt đầu")=5,"Chưa bắt đầu","Đang làm")) -> Chưa bắt đầu | J38: Giấy chứng nhận ĐKDN hoặc trạng thái có ngày · bảng 3 báo giá kế toán + quyết định · hồ sơ affiliate sẵn · cột K trong bảng số · danh sách 10 creator (5 đã nhắn)
A39: 27 | C39: 3.3 Chuyến đi chung thủ công #1 · Kế toán vào việc | D39: [Tuần 27] Quan sát chuyến đi chung · Kế toán vào việc · 5 creator nhận sản phẩm và đăng · Đặt trước tuần 3 · Nội dung kênh thắng | E39: Biết điều kiện tin cậy tối thiểu; kế toán chạy; 5 creator đăng bài. | F39: VH · ĐP · TT · TN | G39: =NGAY_BAT_DAU+182 -> 46461 | H39: =NGAY_BAT_DAU+188 -> 46467 | I39: =IF(COUNTIF('C4_T25-32'!$I$17:$I$21,"Xong")+COUNTIF('C4_T25-32'!$I$17:$I$21,"Cắt")=5,"Xong",IF(COUNTIF('C4_T25-32'!$I$17:$I$21,"Chưa bắt đầu")=5,"Chưa bắt đầu","Đang làm")) -> Chưa bắt đầu | J39: Tệp ghi chép chuyến đi + 5 phỏng vấn sau chuyến · hợp đồng kế toán + lịch làm việc · 5 bài creator có link · bảng số đặt trước tuần 3
A40: 28 | C40: 3.4 Hồ sơ mạng xã hội · Bật affiliate · Xác thực SĐT | D40: [Tuần 28] Hồ sơ mạng xã hội · Chính sách xác thực số điện thoại · Bật link affiliate · Creator tuần 2 · đặt trước tuần 4 | E40: Hồ sơ mạng xã hội ở trạng thái rõ ràng; affiliate chạy hợp pháp; chính sách xác thực công bố. | F40: ĐP · SP · VH · TT | G40: =NGAY_BAT_DAU+189 -> 46468 | H40: =NGAY_BAT_DAU+195 -> 46474 | I40: =IF(COUNTIF('C4_T25-32'!$I$23:$I$26,"Xong")+COUNTIF('C4_T25-32'!$I$23:$I$26,"Cắt")=4,"Xong",IF(COUNTIF('C4_T25-32'!$I$23:$I$26,"Chưa bắt đầu")=4,"Chưa bắt đầu","Đang làm")) -> Chưa bắt đầu | J40: Biên nhận thông báo MXH hoặc kế hoạch giấy phép có hạn · điều khoản cập nhật + tính năng xác thực lên lịch · link affiliate sống + cột bấm/đặt
A41: 29 | C41: 3.5 Đo K · Doanh thu đầu tiên · Quyết định in lô 1 | D41: [Tuần 29] Bảng số + dòng tiền v3 · Quyết định lô in 1 · Đối tác tỉnh 2 · Nội dung | E41: Dòng tiền có số thật; quyết định in hay hoãn; tỉnh 2 khởi động. | F41: ĐP · TN · VH · TT | G41: =NGAY_BAT_DAU+196 -> 46475 | H41: =NGAY_BAT_DAU+202 -> 46481 | I41: =IF(COUNTIF('C4_T25-32'!$I$28:$I$31,"Xong")+COUNTIF('C4_T25-32'!$I$28:$I$31,"Cắt")=4,"Xong",IF(COUNTIF('C4_T25-32'!$I$28:$I$31,"Chưa bắt đầu")=4,"Chưa bắt đầu","Đang làm")) -> Chưa bắt đầu | J41: Sheet dòng tiền v3 (giả định thay bằng số thật) · ADR lô in 1 + hợp đồng in (hoặc lý do hoãn) · bảng 10 đối tác tỉnh 2 + 5 ghi chú cuộc gọi
A42: 30 | C42: 3.6 Kết chu kỳ 4 · Đặt in lô 1 | D42: [Tuần 30] Đặt in lô 1 · Thử ưu đãi mời bạn · Kết 3 cược C4 · Sửa lỗi | E42: Kết 3 cược C4; lô 1 vào xưởng; thử ưu đãi mời bạn. | F42: TN · VH · TT · ALL · SP | G42: =NGAY_BAT_DAU+203 -> 46482 | H42: =NGAY_BAT_DAU+209 -> 46488 | I42: =IF(COUNTIF('C4_T25-32'!$I$33:$I$36,"Xong")+COUNTIF('C4_T25-32'!$I$33:$I$36,"Cắt")=4,"Xong",IF(COUNTIF('C4_T25-32'!$I$33:$I$36,"Chưa bắt đầu")=4,"Chưa bắt đầu","Đang làm")) -> Chưa bắt đầu | J42: Đơn in lô 1 · thiết lập ưu đãi mời bạn + số nền · biên bản kết C4
...

Sheet C1_T01-08
A1: C1 · CHU KỲ 1 — Khám phá khách hàng
A2: ="Tuần 01 – 08 │ "&TEXT(NGAY_BAT_DAU+0,"dd/mm/yyyy")&" → "&TEXT(NGAY_BAT_DAU+55,"dd/mm/yyyy")&" │ 6 tuần làm (T1–T6) + 2 tuần nguội (T7–T8) │ QUÝ 1 — GIAI ĐOẠN 1: THẤU CẢM" -> Tuần 01 – 08 │ 14/09/2026 → 08/11/2026 │ 6 tuần làm (T1–T6) + 2 tuần nguội (T7–T8) │ QUÝ 1 — GIAI ĐOẠN 1: THẤU CẢM
A4: STT | B4: Giai đoạn / Phase | C4: Đầu mục / Task | D4: Phân việc chi tiết / Subtask | E4: Mục đích / Purpose | F4: Ghế / PIC | G4: Ngày bắt đầu Start Date | H4: Ngày kết thúc End Date | I4: Trạng thái / Status | J4: Tiêu chí hoàn thành / Output | K4: Ghi chú / Note
A5: ="📅 TUẦN 01 · "&TEXT(NGAY_BAT_DAU+0,"dd/mm/yyyy")&" – "&TEXT(NGAY_BAT_DAU+6,"dd/mm/yyyy")&" — Khởi động dự án (M1) — chốt cách làm việc │ 🎯 Mục tiêu: Ra khỏi tuần với 9 quyết định, ghế có tên, lịch họp đã gửi, và đủ vật liệu để phỏng vấn từ tuần 2. │ 💡 Cuối tuần bi"&"ết được: Một câu «kinh doanh gì» cả nhóm nói giống nhau; 5 người thật là khách đầu tiên; ai cầm ghế nào với bao nhiêu giờ; 30–40 người sẽ được hỏi bằng kịch bản nào." -> 📅 TUẦN 01 · 14/09/2026 – 20/09/2026 — Khởi động dự án (M1) — chốt cách làm việc │ 🎯 Mục tiêu: Ra khỏi tuần với 9 quyết định, ghế có tên, lịch họp đã gửi, và đủ vật liệu để phỏng vấn từ tuần 2. │ 💡 Cuối tuần biết được: Một câu «kinh doanh gì» cả nhóm nói giống nhau; 5 người thật là khách đầu tiên; ai cầm ghế nào với bao nhiêu giờ; 30–40 người sẽ được hỏi bằng kịch bản nào.
A6: 1 | B6: QUÝ 1 — GIAI ĐOẠN 1: THẤU CẢM | C6: T01.1 Tầm nhìn v0 | D6: Đọc 4 câu trả lời riêng của từng người (bài tập trước họp). Chọn một câu «Levart kinh doanh gì» và một câu «khách đầu tiên». Chép câu của nhóm vào Phụ lục E. Ký tên, ghi ngày. Giới hạn 20 phút. | F6: TN | G6: =NGAY_BAT_DAU+0 -> 46279 | H6: =NGAY_BAT_DAU+6 -> 46285 | I6: Chưa bắt đầu | J6: Một trang tầm nhìn v0 có ngày, có tên người ký
A7: 2 | C7: T01.2 Phân loại du lịch (nháp) | D7: Liệt kê 6–8 loại theo cách người trẻ tự gọi: nghỉ dưỡng, khám phá văn hoá–ẩm thực, trekking/mạo hiểm, check-in/chụp ảnh, chữa lành, lễ hội, phượt xe máy, công tác kết hợp. Đánh dấu rõ: dùng để HỎI, chưa chốt. | F7: TN | G7: =NGAY_BAT_DAU+0 -> 46279 | H7: =NGAY_BAT_DAU+6 -> 46285 | I7: Chưa bắt đầu | J7: docs/01_khach-hang/phan-loai-v0.md
A8: 3 | C8: T01.3 Xác định vấn đề (giả thuyết) | D8: Mỗi người viết 2 nỗi đau dạng «Khi ___, tôi muốn ___, nhưng ___». Gom, bỏ trùng, giữ 3–4. Ghi rõ đây là giả thuyết sẽ kiểm ở T3–T6. | F8: ALL | G8: =NGAY_BAT_DAU+0 -> 46279 | H8: =NGAY_BAT_DAU+6 -> 46285 | I8: Chưa bắt đầu | J8: docs/01_khach-hang/noi-dau-gia-thuyet.md
A9: 4 | C9: T01.4 Tập khách hàng target (dự kiến) | D9: Một câu mô tả đầu cầu (đề xuất: 18–25 tuổi, Hà Nội, đi tự túc ≥ 1 lần/12 tháng). Kiểm bằng cách chỉ ra 5 người THẬT khớp mô tả trong danh sách 30–40 tên. | F9: TT | G9: =NGAY_BAT_DAU+0 -> 46279 | H9: =NGAY_BAT_DAU+6 -> 46285 | I9: Chưa bắt đầu | J9: Câu mô tả + 5 tên thật trong tệp persona v0
A10: 5 | C10: T01.5 Vai trò từng thành viên | D10: Điền BẢNG GIỜ trước, BẢNG GHẾ sau. Ghế ĐP giao người có giờ ổn định nhất. Tổng giờ < 12/tuần thì chu kỳ 1 chỉ giữ 2 cược thay vì 3. | F10: ĐP | G10: =NGAY_BAT_DAU+0 -> 46279 | H10: =NGAY_BAT_DAU+6 -> 46285 | I10: Chưa bắt đầu | J10: Bảng ghế + bảng giờ có tên, lưu docs/05_phap-ly-tai-chinh/
A11: 6 | C11: T01.6 Kịch bản phỏng vấn v0 | D11: Lấy Phụ lục A Business.md; đối chiếu 6 nhóm câu hỏi của nhóm + 2 nhóm bổ sung (tiền đã chi, giữ gì sau chuyến đi). Mỗi nhóm ≥ 1 câu hỏi về CHUYẾN GẦN NHẤT, không hỏi chung chung. | F11: TT | G11: =NGAY_BAT_DAU+0 -> 46279 | H11: =NGAY_BAT_DAU+6 -> 46285 | I11: Chưa bắt đầu | J11: docs/01_khach-hang/kich-ban-v0.md
A12: 7 | C12: T01.7 Danh sách phỏng vấn | D12: Gộp 10 tên/người đã nộp trước họp thành một bảng: tên · tuổi · học/làm · đã đi tự túc? · quan hệ · ai hẹn. Đánh dấu ai đúng đầu cầu, loại ai không. | F12: ALL | G12: =NGAY_BAT_DAU+0 -> 46279 | H12: =NGAY_BAT_DAU+6 -> 46285 | I12: Chưa bắt đầu | J12: Bảng 30–40 dòng; cần ≥ 30 người đúng đầu cầu
A13: 8 | C13: T01.8 MVP — sơ đồ luồng sử dụng app (as-is) | D13: Vẽ 1 trang luồng HIỆN CÓ: mở app → đăng nhập/khách → xem bảng tin → lập lịch trình → check-in đóng dấu → chia sẻ. Ghi ở mỗi bước: đã có / chưa có / hỏng. Không xây gì. | F13: SP | G13: =NGAY_BAT_DAU+0 -> 46279 | H13: =NGAY_BAT_DAU+6 -> 46285 | I13: Chưa bắt đầu | J13: docs/02_thi-nghiem/luong-as-is.md (1 trang)
A14: 9 | C14: T01.9 Lịch họp tuần, thư mục docs/, bãi đỗ ý tưởng | D14: Gửi lời mời lịch trong 10 phút cuối họp. Tạo cây docs/ theo Business.md 8.4; chép Phụ lục B–F thành tệp mẫu; tạo 07_bai-do/bai-do.md và ghi ngay các ý đã nêu trong họp. | F14: ĐP | G14: =NGAY_BAT_DAU+0 -> 46279 | H14: =NGAY_BAT_DAU+6 -> 46285 | I14: Chưa bắt đầu | J14: Lịch đã gửi · thư mục có 5 mẫu · bãi đỗ ≥ 5 dòng
A15: 10 | C15: T01.10 Danh sách 12 người thử nghiệm kín | D15: Chọn 12 người từ danh sách phỏng vấn, đồng ý cài bản thử và giữ liên tục 14 ngày; ghi email Google của họ. (Yêu cầu bắt buộc của Google Play với tài khoản cá nhân.) | F15: SP | G15: =NGAY_BAT_DAU+0 -> 46279 | H15: =NGAY_BAT_DAU+6 -> 46285 | I15: Chưa bắt đầu | J15: Bảng 12 tên + email Google
A16: 11 | C16: T01.11 Biên bản M1 | D16: Ghi trực tiếp trong họp theo next meeting propose.md phần 7 — 9 quyết định, mỗi quyết định một dấu tick. | F16: ĐP | G16: =NGAY_BAT_DAU+0 -> 46279 | H16: =NGAY_BAT_DAU+6 -> 46285 | I16: Chưa bắt đầu | J16: docs/06_hop/2026-09-1x-M1.md
A17: ="📅 TUẦN 02 · "&TEXT(NGAY_BAT_DAU+7,"dd/mm/yyyy")&" – "&TEXT(NGAY_BAT_DAU+13,"dd/mm/yyyy")&" — Phỏng vấn thử · Số liệu thị trường · Đối thủ │ 🎯 Mục tiêu: Kịch bản chạy được trên người thật; thị trường có số có nguồn; đối thủ có ảnh chụp; tỉnh mục tiêu được chốt. │ 💡"&" Cuối tuần biết được: Kịch bản v1 dùng được; đối thủ đang làm tốt gì và trống ở đâu; cỡ thị trường theo số có nguồn (hoặc biết chính xác còn thiếu biến nào); tỉnh mục tiêu và 10 đố"&"i tác đầu." -> 📅 TUẦN 02 · 21/09/2026 – 27/09/2026 — Phỏng vấn thử · Số liệu thị trường · Đối thủ │ 🎯 Mục tiêu: Kịch bản chạy được trên người thật; thị trường có số có nguồn; đối thủ có ảnh chụp; tỉnh mục tiêu được chốt. │ 💡 Cuối tuần biết được: Kịch bản v1 dùng được; đối thủ đang làm tốt gì và trống ở đâu; cỡ thị trường theo số có nguồn (hoặc biết chính xác còn thiếu biến nào); tỉnh mục tiêu và 10 đối tác đầu.
A18: 12 | B18: QUÝ 1 — GIAI ĐOẠN 1: THẤU CẢM | C18: T02.1 2 phỏng vấn thử | D18: Chọn 2 người dễ hẹn nhưng đúng đầu cầu. 30'/cuộc, ghi âm có xin phép. Sau mỗi cuộc dành 10' ghi: câu nào bị trả lời chung chung, câu nào vô tình dẫn dắt, thứ tự nào làm họ mở lòng. Sửa thành v1, ghi «thay đổi so với v0» ở đầu tệp. | F18: TT | G18: =NGAY_BAT_DAU+7 -> 46286 | H18: =NGAY_BAT_DAU+13 -> 46292 | I18: Chưa bắt đầu | J18: 2 tệp phỏng vấn + kich-ban-v1.md gửi nhóm trước T3
A19: 13 | C19: T02.2 Bảng so sánh 6 app đối thủ | D19: 6 app theo 6 nhóm: 2 OTA, 1 bản đồ, 1 lịch trình, 1 mạng xã hội, 1 app Việt. Mỗi app 30', đóng vai người sắp đi tỉnh mục tiêu với 3 nhiệm vụ: lên kế hoạch 3 ngày / lưu kỷ niệm / tìm người đi cùng. Chụp màn hình từng bước. | F19: TN · SP | G19: =NGAY_BAT_DAU+7 -> 46286 | H19: =NGAY_BAT_DAU+13 -> 46292 | I19: Chưa bắt đầu | J19: Bảng 6 hàng × 5 trục + 2 cột «làm tốt nhất» và «khoảng trống», có ảnh
A20: 14 | C20: T02.3 Research số liệu du lịch | D20: Theo Phụ lục B week_index. Bảng: chỉ số · giá trị · năm · nguồn (link) · độ tin (chính thức/báo chí/ước). Điền 4 biến công thức cỡ thị trường; biến nào không có thì ghi «chưa có, cần khảo sát» thay vì đoán. | F20: ĐP | G20: =NGAY_BAT_DAU+7 -> 46286 | H20: =NGAY_BAT_DAU+13 -> 46292 | I20: Chưa bắt đầu | J20: Tệp có ≥ 8 dòng có link; công thức có ≥ 2/4 biến
A21: 15 | C21: T02.4 Chọn tỉnh mục tiêu → ADR | D21: Chấm 3 ứng viên (Hà Giang, Ninh Bình, Mộc Châu) theo 4 tiêu chí 1–3 điểm: (a) ≥50% danh sách phỏng vấn đã/định đi; (b) đi được cuối tuần từ Hà Nội; (c) mùa đẹp rơi vào T13–T30; (d) nhiều homestay/quán nhỏ. Cao điểm nhất thắng. | F21: VH | G21: =NGAY_BAT_DAU+7 -> 46286 | H21: =NGAY_BAT_DAU+13 -> 46292 | I21: Chưa bắt đầu | J21: docs/00_quyet-dinh/2026-09-2x-tinh-muc-tieu.md
A22: 16 | C22: T02.5 Danh sách 10 đối tác tỉnh mục tiêu | D22: Nguồn: Google Maps đọc tay ghi thông tin liên hệ công khai (KHÔNG cào hàng loạt — vi phạm điều khoản), fanpage, nhóm review. Ưu tiên chủ trẻ đang chạy fanpage. | F22: VH | G22: =NGAY_BAT_DAU+7 -> 46286 | H22: =NGAY_BAT_DAU+13 -> 46292 | I22: Chưa bắt đầu | J22: 10 dòng: tên · loại · khu vực · liên hệ · kênh họ dùng · trạng thái
A23: 17 | C23: T02.6 Khởi tạo bảng số tuần | D23: Sheet cột: phỏng vấn cộng dồn · đối tác đã gọi · giờ đã góp (từng người) · việc tuần xong/tổng. Điền tuần 2. | F23: ĐP | G23: =NGAY_BAT_DAU+7 -> 46286 | H23: =NGAY_BAT_DAU+13 -> 46292 | I23: Chưa bắt đầu | J23: Sheet có dòng T2
A24: ="📅 TUẦN 03 · "&TEXT(NGAY_BAT_DAU+14,"dd/mm/yyyy")&" – "&TEXT(NGAY_BAT_DAU+20,"dd/mm/yyyy")&" — Phỏng vấn đợt 1 · Ký thoả thuận đồng sáng lập (M3) │ 🎯 Mục tiêu: ≥ 8 phỏng vấn có tệp; thoả thuận đồng sáng lập ký; họp tuần theo cấu trúc Level 10 lần đầu. │ 💡 Cuối tuần "&"biết được: Nỗi đau nào xuất hiện ≥ 2 lần trong 8 cuộc đầu; đối tác đang tìm khách trẻ bằng kênh gì và tốn bao nhiêu." -> 📅 TUẦN 03 · 28/09/2026 – 04/10/2026 — Phỏng vấn đợt 1 · Ký thoả thuận đồng sáng lập (M3) │ 🎯 Mục tiêu: ≥ 8 phỏng vấn có tệp; thoả thuận đồng sáng lập ký; họp tuần theo cấu trúc Level 10 lần đầu. │ 💡 Cuối tuần biết được: Nỗi đau nào xuất hiện ≥ 2 lần trong 8 cuộc đầu; đối tác đang tìm khách trẻ bằng kênh gì và tốn bao nhiêu.
A25: 18 | B25: QUÝ 1 — GIAI ĐOẠN 1: THẤU CẢM | C25: T03.1 ≥ 8 phỏng vấn khách hàng | D25: Mỗi người 2 cuộc/tuần. Hẹn qua chat, 30', ưu tiên gặp trực tiếp hoặc gọi video. Ghi tệp trong ≤ 24 giờ theo 8 cột + ≥ 3 câu trích nguyên văn + 1 dòng «học được» + 1 dòng «giả thuyết bị lay». TT đọc từng tệp, trả lại nếu thiếu trích dẫn. | F25: ALL | G25: =NGAY_BAT_DAU+14 -> 46293 | H25: =NGAY_BAT_DAU+20 -> 46299 | I25: Chưa bắt đầu | J25: 8 tệp docs/01_khach-hang/; bảng theo dõi cập nhật
A26: 19 | C26: T03.2 Ký thoả thuận đồng sáng lập | D26: Nội dung tối thiểu: (a) ghế và trách nhiệm; (b) ghi giờ và chia phần theo đóng góp thật; (c) mọi thứ tạo ra thuộc dự án/DN tương lai; (d) rời đi giữ phần đã góp, không rút IP; (e) sửa thoả thuận cần đồng thuận; (f) bảo mật. Đọc to từng điều trong họp rồi ký. | F26: ĐP | G26: =NGAY_BAT_DAU+14 -> 46293 | H26: =NGAY_BAT_DAU+20 -> 46299 | I26: Chưa bắt đầu | J26: PDF có chữ ký mọi người, lưu docs/05_phap-ly-tai-chinh/
A27: 20 | C27: T03.3 Mở bảng ghi giờ | D27: Sheet: ngày · người · việc · giờ · loại (làm/họp/học). Mỗi người tự ghi cuối ngày; ĐP chốt sáng thứ Hai và đưa tổng vào bảng số. Đây là dữ liệu chia phần và tính CAC bằng giờ. | F27: ĐP | G27: =NGAY_BAT_DAU+14 -> 46293 | H27: =NGAY_BAT_DAU+20 -> 46299 | I27: Chưa bắt đầu | J27: Sheet có dòng của mọi người tuần 3
A28: 21 | C28: T03.4 Họp Level 10 lần đầu | D28: Chạy đúng 7 khúc theo Phụ lục C Business.md; có người canh giờ; danh sách vấn đề ghi riêng; chấm điểm buổi họp cuối buổi. | F28: ĐP | G28: =NGAY_BAT_DAU+14 -> 46293 | H28: =NGAY_BAT_DAU+20 -> 46299 | I28: Chưa bắt đầu | J28: Biên bản có bảng số, danh sách vấn đề, việc tuần có tên người
A29: 22 | C29: T03.5 Gọi 2 đối tác đầu tiên | D29: Kịch bản 10': giới thiệu 1 câu (sinh viên làm dự án du lịch, muốn hiểu cách anh/chị tìm khách trẻ). 5 câu: khách trẻ đến từ đâu · đang dùng kênh nào trả bao nhiêu · bực gì nhất · mùa nào vắng · nếu có 30 bạn trẻ tới trong tháng thì sẵn lòng làm gì. Mục đích là NGHE, không bán. | F29: VH | G29: =NGAY_BAT_DAU+14 -> 46293 | H29: =NGAY_BAT_DAU+20 -> 46299 | I29: Chưa bắt đầu | J29: 2 dòng bảng đối tác có trạng thái + ghi chú
A30: 23 | C30: T03.6 Marketing trên các nền tảng — 1 trang | D30: Đọc, chưa chạy: trang trợ giúp Play về trang cửa hàng; cách đề xuất của TikTok/Threads ở mức phổ thông; 5 nhóm Facebook du lịch lớn (tên, số thành viên, quy tắc đăng); mạng affiliate ở Việt Nam (điều kiện tham gia — cần kiểm chứng). | F30: TN | G30: =NGAY_BAT_DAU+14 -> 46293 | H30: =NGAY_BAT_DAU+20 -> 46299 | I30: Chưa bắt đầu | J30: docs/03_tang-truong/marketing-nen-tang.md — nền cho Bullseye T15
A31: ="📅 TUẦN 04 · "&TEXT(NGAY_BAT_DAU+21,"dd/mm/yyyy")&" – "&TEXT(NGAY_BAT_DAU+27,"dd/mm/yyyy")&" — Phỏng vấn ≥ 16 · Nhãn hiệu · Affiliate │ 🎯 Mục tiêu: Cộng dồn 16 phỏng vấn; biết tên Levart dùng được không; biết affiliate mở cho ai; sẵn câu hỏi cho buổi luật. │ 💡 Cuối "&"tuần biết được: Tên dùng được hay phải đổi; chương trình affiliate nào mở cho nhóm/DN mới; nỗi đau nào đang dẫn đầu bảng đếm." -> 📅 TUẦN 04 · 05/10/2026 – 11/10/2026 — Phỏng vấn ≥ 16 · Nhãn hiệu · Affiliate │ 🎯 Mục tiêu: Cộng dồn 16 phỏng vấn; biết tên Levart dùng được không; biết affiliate mở cho ai; sẵn câu hỏi cho buổi luật. │ 💡 Cuối tuần biết được: Tên dùng được hay phải đổi; chương trình affiliate nào mở cho nhóm/DN mới; nỗi đau nào đang dẫn đầu bảng đếm.
A32: 24 | B32: QUÝ 1 — GIAI ĐOẠN 1: THẤU CẢM | C32: T04.1 ≥ 8 phỏng vấn (cộng dồn 16) | D32: Như T3. | F32: ALL | G32: =NGAY_BAT_DAU+21 -> 46300 | H32: =NGAY_BAT_DAU+27 -> 46306 | I32: Chưa bắt đầu | J32: 16 tệp phỏng vấn
A33: 25 | C33: T04.2 Bảng đếm nỗi đau | D33: Sheet: dòng = một nỗi đau (gộp các cách nói khác nhau về cùng một việc); cột = số người nêu KHÔNG GỢI · có gợi · tần suất TB · hài lòng TB · số người đã chi tiền · trích dẫn tiêu biểu (mã tệp). Cập nhật sau mỗi tệp mới. | F33: TT | G33: =NGAY_BAT_DAU+21 -> 46300 | H33: =NGAY_BAT_DAU+27 -> 46306 | I33: Chưa bắt đầu | J33: Sheet phủ đủ 16 tệp — nguồn cho top 3 ở T7
A34: 26 | C34: T04.3 Tra nhãn hiệu «Levart» | D34: Tra Levart và biến thể trên cơ sở dữ liệu Cục Sở hữu trí tuệ và WIPO Global Brand Database, nhóm 9/35/39/41/42; tra tên miền; tra Play & App Store xem có app trùng tên. Chụp màn hình kết quả. Nếu trùng thì đưa vào danh sách vấn đề (đổi tên là quyết định cửa một chiều). | F34: ĐP | G34: =NGAY_BAT_DAU+21 -> 46300 | H34: =NGAY_BAT_DAU+27 -> 46306 | I34: Chưa bắt đầu | J34: Tệp kết quả + ảnh chụp trong docs/05_
A35: 27 | C35: T04.4 Mua tên miền | D35: .vn và .com (nếu còn). Đứng tên một cá nhân tạm; ghi vào thoả thuận là tài sản dự án; chuyển sang DN ở T26+. Ghi sổ quỹ. | F35: ĐP | G35: =NGAY_BAT_DAU+21 -> 46300 | H35: =NGAY_BAT_DAU+27 -> 46306 | I35: Chưa bắt đầu | J35: Hoá đơn + dòng sổ quỹ
A36: 28 | C36: T04.5 5 câu hỏi luật + đặt hẹn | D36: Soạn 5 câu kèm 1 trang mô tả app (có bảng tin, GPS, ảnh, khách ẩn danh, chưa doanh thu). Gửi trước cho người hiểu luật; hẹn 45' trong T5. | F36: ĐP | G36: =NGAY_BAT_DAU+21 -> 46300 | H36: =NGAY_BAT_DAU+27 -> 46306 | I36: Chưa bắt đầu | J36: Lịch hẹn đã chốt + tệp câu hỏi
A37: 29 | C37: T04.6 Gọi 3 đối tác còn lại | D37: Như T3. | F37: VH | G37: =NGAY_BAT_DAU+21 -> 46300 | H37: =NGAY_BAT_DAU+27 -> 46306 | I37: Chưa bắt đầu | J37: 5/5 dòng bảng đối tác có trạng thái
A38: 30 | C38: T04.7 Bảng 3 chương trình affiliate | D38: Chọn 1 lưu trú, 1 vé (xe khách/máy bay), 1 sàn TMĐT. Đọc điều khoản: đối tượng (cá nhân/DN) · cách duyệt · hoa hồng · thời hạn ghi nhận (cookie) · điều cấm · ngưỡng thanh toán · link điều khoản · ngày đọc. | F38: VH | G38: =NGAY_BAT_DAU+21 -> 46300 | H38: =NGAY_BAT_DAU+27 -> 46306 | I38: Chưa bắt đầu | J38: Bảng 3 dòng × 8 cột trong docs/04_doi-tac/affiliate.md
A39: 31 | C39: T04.8 Gom phản hồi về app | D39: Một tệp, mỗi phỏng vấn một dòng: bấm gì đầu tiên · hiểu app làm gì (nguyên văn) · bực ở đâu. KHÔNG sửa app. | F39: SP | G39: =NGAY_BAT_DAU+21 -> 46300 | H39: =NGAY_BAT_DAU+27 -> 46306 | I39: Chưa bắt đầu | J39: 16 dòng — đầu vào cho luồng to-be T6
A40: ="📅 TUẦN 05 · "&TEXT(NGAY_BAT_DAU+28,"dd/mm/yyyy")&" – "&TEXT(NGAY_BAT_DAU+34,"dd/mm/yyyy")&" — Phỏng vấn ≥ 24 · Buổi hỏi luật │ 🎯 Mục tiêu: Cộng dồn 24 phỏng vấn; có câu trả lời thật cho 5 câu luật; biết ai đau nhất; biết đối tác nào sẵn lòng thử. │ 💡 Cuối tuần biết"&" được: Dưới 1.000 người có phải thông báo mạng xã hội không; khách ẩn danh có được đăng bài không; khi nào bắt buộc lập doanh nghiệp; phân khúc nào đau nhất; loại du lịch phổ biến "&"trong đầu cầu." -> 📅 TUẦN 05 · 12/10/2026 – 18/10/2026 — Phỏng vấn ≥ 24 · Buổi hỏi luật │ 🎯 Mục tiêu: Cộng dồn 24 phỏng vấn; có câu trả lời thật cho 5 câu luật; biết ai đau nhất; biết đối tác nào sẵn lòng thử. │ 💡 Cuối tuần biết được: Dưới 1.000 người có phải thông báo mạng xã hội không; khách ẩn danh có được đăng bài không; khi nào bắt buộc lập doanh nghiệp; phân khúc nào đau nhất; loại du lịch phổ biến trong đầu cầu.
A41: 32 | B41: QUÝ 1 — GIAI ĐOẠN 1: THẤU CẢM | C41: T05.1 ≥ 8 phỏng vấn (cộng dồn 24) | D41: Như T3. | F41: ALL | G41: =NGAY_BAT_DAU+28 -> 46307 | H41: =NGAY_BAT_DAU+34 -> 46313 | I41: Chưa bắt đầu | J41: 24 tệp phỏng vấn
...

Sheet C2_T09-16
A1: C2 · CHU KỲ 2 — Cohort đầu tiên & Cổng quý 1
A2: ="Tuần 09 – 16 │ "&TEXT(NGAY_BAT_DAU+56,"dd/mm/yyyy")&" → "&TEXT(NGAY_BAT_DAU+111,"dd/mm/yyyy")&" │ 6 tuần làm (T9–T14) + 2 tuần nguội (T15–T16, trùng kỳ thi & Tết Dương) │ QUÝ 1 — GIAI ĐOẠN 1: THẤU CẢM" -> Tuần 09 – 16 │ 09/11/2026 → 03/01/2027 │ 6 tuần làm (T9–T14) + 2 tuần nguội (T15–T16, trùng kỳ thi & Tết Dương) │ QUÝ 1 — GIAI ĐOẠN 1: THẤU CẢM
A4: STT | B4: Giai đoạn / Phase | C4: Đầu mục / Task | D4: Phân việc chi tiết / Subtask | E4: Mục đích / Purpose | F4: Ghế / PIC | G4: Ngày bắt đầu Start Date | H4: Ngày kết thúc End Date | I4: Trạng thái / Status | J4: Tiêu chí hoàn thành / Output | K4: Ghi chú / Note
A5: ="📅 TUẦN 09 · "&TEXT(NGAY_BAT_DAU+56,"dd/mm/yyyy")&" – "&TEXT(NGAY_BAT_DAU+62,"dd/mm/yyyy")&" — Thử nghiệm kín 12 người · Phỏng vấn lần 2 │ 🎯 Mục tiêu: Đồng hồ 14 ngày của Google Play bắt đầu; phễu có số thật đầu tiên; 5 phỏng vấn lần 2; 3 nội dung đầu. │ 💡 Cuối tuần"&" biết được: Người lần đầu nhìn app có hiểu «hộ chiếu» trong 5 giây không (từ 5 phỏng vấn); 12 người đã cài; phễu đo được." -> 📅 TUẦN 09 · 09/11/2026 – 15/11/2026 — Thử nghiệm kín 12 người · Phỏng vấn lần 2 │ 🎯 Mục tiêu: Đồng hồ 14 ngày của Google Play bắt đầu; phễu có số thật đầu tiên; 5 phỏng vấn lần 2; 3 nội dung đầu. │ 💡 Cuối tuần biết được: Người lần đầu nhìn app có hiểu «hộ chiếu» trong 5 giây không (từ 5 phỏng vấn); 12 người đã cài; phễu đo được.
A6: 1 | B6: QUÝ 1 — GIAI ĐOẠN 1: THẤU CẢM | C6: T09.1 Thử nghiệm kín 12 người | D6: Tạo bản thử kín; thêm 12 email; gửi hướng dẫn cài 3 bước; xác nhận từng người đã cài VÀ mở app; ghi ngày bắt đầu (đủ 14 ngày rơi vào T11); nhắc không gỡ. | F6: SP | G6: =NGAY_BAT_DAU+56 -> 46335 | H6: =NGAY_BAT_DAU+62 -> 46341 | I6: Chưa bắt đầu | J6: Bảng 12 người «đã cài» + ngày bắt đầu
A7: 2 | C7: T09.2 Phễu đo hoạt động | D7: Kiểm 5 hành vi được ghi nhận: mở lần đầu · đóng dấu đầu · quay lại · chia sẻ · bấm đối tác. ĐP lập dashboard đơn giản (sheet nhập tay hằng tuần nếu cần). | F7: SP · ĐP | G7: =NGAY_BAT_DAU+56 -> 46335 | H7: =NGAY_BAT_DAU+62 -> 46341 | I7: Chưa bắt đầu | J7: Bảng số T9 có cột kích hoạt với số thật (dù nhỏ)
A8: 3 | C8: T09.3 5 phỏng vấn lần 2 | D8: Theo kịch bản T8. Tệp ghi: đúng/sai top 3 · hiểu định vị (có/không + nguyên văn) · thẻ giá chọn · dịch vụ top và dịch vụ gạch · điều kiện đi chung. | F8: TT | G8: =NGAY_BAT_DAU+56 -> 46335 | H8: =NGAY_BAT_DAU+62 -> 46341 | I8: Chưa bắt đầu | J8: 5 tệp phỏng vấn lần 2
A9: 4 | C9: T09.4 3 nội dung ngắn đầu tiên | D9: Chủ đề: (1) «tôi đã đi X/34 tỉnh — bạn?» (2) «3 chỗ ở [tỉnh] không có trên bản đồ» (3) «hộ chiếu du lịch là gì». 15–30 giây, quay điện thoại, có hình con dấu. Đăng 1 kênh chính, đăng lại kênh 2. Ghi link + giờ đăng; đo sau 7 ngày. | F9: TT | G9: =NGAY_BAT_DAU+56 -> 46335 | H9: =NGAY_BAT_DAU+62 -> 46341 | I9: Chưa bắt đầu | J9: 3 link trong docs/03_/noi-dung.md
A10: 5 | C10: T09.5 Ưu đãi đối tác — 1 trang | D10: Với 3 đối tác đồng ý: ưu đãi nhỏ ít tốn đối tác (đồ uống/giảm 10%) cho người CHO XEM CON DẤU TỈNH trong app; cách xác nhận (xem màn hình); thời hạn T10–T14; cách đối tác báo lại số người. | F10: VH | G10: =NGAY_BAT_DAU+56 -> 46335 | H10: =NGAY_BAT_DAU+62 -> 46341 | I10: Chưa bắt đầu | J10: 3 đối tác xác nhận qua chat
A11: 6 | C11: T09.6 Công khai trang tĩnh | D11: Chính sách riêng tư + điều khoản v1 lên trang; đưa link vào app và trang cửa hàng. | F11: ĐP | G11: =NGAY_BAT_DAU+56 -> 46335 | H11: =NGAY_BAT_DAU+62 -> 46341 | I11: Chưa bắt đầu | J11: Link mở được, có ngày hiệu lực
A12: ="📅 TUẦN 10 · "&TEXT(NGAY_BAT_DAU+63,"dd/mm/yyyy")&" – "&TEXT(NGAY_BAT_DAU+69,"dd/mm/yyyy")&" — Cohort 30 người · Phân tích lần 2 · Slogan │ 🎯 Mục tiêu: 30 người dùng thật có nguồn; kết quả 10 phỏng vấn lần 2; slogan v1 chọn bằng người ngoài. │ 💡 Cuối tuần biết được:"&" % cohort đóng con dấu đầu trong 7 ngày; slogan v1; mức giá được chọn nhiều nhất và dịch vụ nào họ muốn đặt." -> 📅 TUẦN 10 · 16/11/2026 – 22/11/2026 — Cohort 30 người · Phân tích lần 2 · Slogan │ 🎯 Mục tiêu: 30 người dùng thật có nguồn; kết quả 10 phỏng vấn lần 2; slogan v1 chọn bằng người ngoài. │ 💡 Cuối tuần biết được: % cohort đóng con dấu đầu trong 7 ngày; slogan v1; mức giá được chọn nhiều nhất và dịch vụ nào họ muốn đặt.
A13: 7 | B13: QUÝ 1 — GIAI ĐOẠN 1: THẤU CẢM | C13: T10.1 Mời cohort lên 30 người | D13: Kênh: CLB du lịch/nhiếp ảnh, nhóm lớp, bạn của 12 người. Lời mời 3 câu + link. Điều kiện: cài, đăng ký, thử đóng 1 con dấu trong tuần (Hà Nội cũng tính). Lập nhóm chat cohort để hỗ trợ. Ghi NGUỒN từng người. | F13: TT | G13: =NGAY_BAT_DAU+63 -> 46342 | H13: =NGAY_BAT_DAU+69 -> 46348 | I13: Chưa bắt đầu | J13: Bảng cohort 30 dòng: tên · kênh · ngày cài · đã đóng dấu?
A14: 8 | C14: T10.2 5 phỏng vấn lần 2 còn lại + phân tích | D14: Tổng hợp 10 cuộc: % xác nhận top 3 · % hiểu định vị đúng · phân bố thẻ giá (biểu đồ cột) · top 3 dịch vụ muốn đặt · 5 điều kiện đi chung hay gặp · kết luận 5 dòng. | F14: TT | G14: =NGAY_BAT_DAU+63 -> 46342 | H14: =NGAY_BAT_DAU+69 -> 46348 | I14: Chưa bắt đầu | J14: docs/01_/phong-van-lan-2-ket-qua.md
A15: 9 | C15: T10.3 Thử 3 slogan với 20 người ngoài nhóm | D15: 3 ảnh giống nhau, khác câu. 20 người chưa biết app, mỗi người xem 1 ảnh 5 giây → «app này làm gì?» và «nhớ câu gì?». Ghi đúng/sai. Chọn câu có tỷ lệ hiểu đúng + nhớ cao nhất. KHÔNG biểu quyết nội bộ. | F15: TN | G15: =NGAY_BAT_DAU+63 -> 46342 | H15: =NGAY_BAT_DAU+69 -> 46348 | I15: Chưa bắt đầu | J15: Bảng 20 dòng + ADR slogan v1
A16: 10 | C16: T10.4 Chạy ưu đãi đối tác | D16: Thông báo cohort: ai đi tỉnh mục tiêu T10–T14 thì dùng. Ghi từng trường hợp: ai · đối tác nào · đối tác nói gì. | F16: VH | G16: =NGAY_BAT_DAU+63 -> 46342 | H16: =NGAY_BAT_DAU+69 -> 46348 | I16: Chưa bắt đầu | J16: Bảng theo dõi ưu đãi
A17: 11 | C17: T10.5 Theo dõi lỗi cohort | D17: Kênh báo lỗi trong nhóm chat. Bảng lỗi: mô tả · ai · thiết bị · mức. CHỈ sửa lỗi chặn (không mở được, mất dữ liệu). Không thêm tính năng. | F17: SP | G17: =NGAY_BAT_DAU+63 -> 46342 | H17: =NGAY_BAT_DAU+69 -> 46348 | I17: Chưa bắt đầu | J17: Bảng lỗi
A18: 12 | C18: T10.6 3 nội dung tiếp theo | D18: Như T9. | F18: TT | G18: =NGAY_BAT_DAU+63 -> 46342 | H18: =NGAY_BAT_DAU+69 -> 46348 | I18: Chưa bắt đầu | J18: 6/10 nội dung
A19: ="📅 TUẦN 11 · "&TEXT(NGAY_BAT_DAU+70,"dd/mm/yyyy")&" – "&TEXT(NGAY_BAT_DAU+76,"dd/mm/yyyy")&" — Đo kích hoạt & quay lại · Dòng tiền v0 │ 🎯 Mục tiêu: Bảng số có 4 chỉ số thật; biết chi phí cố định 12 tháng; 10 nội dung có số; sẵn khảo sát. │ 💡 Cuối tuần biết được: Kên"&"h nào cho cài thật; chi phí cố định 12 tháng và ai đang ứng; CAC bằng giờ." -> 📅 TUẦN 11 · 23/11/2026 – 29/11/2026 — Đo kích hoạt & quay lại · Dòng tiền v0 │ 🎯 Mục tiêu: Bảng số có 4 chỉ số thật; biết chi phí cố định 12 tháng; 10 nội dung có số; sẵn khảo sát. │ 💡 Cuối tuần biết được: Kênh nào cho cài thật; chi phí cố định 12 tháng và ai đang ứng; CAC bằng giờ.
A20: 13 | B20: QUÝ 1 — GIAI ĐOẠN 1: THẤU CẢM | C20: T11.1 Bảng số T11 | D20: Kích hoạt = đóng dấu đầu ≤ 7 ngày / số cài, theo kênh. Quay lại 7 ngày = mở lại sau ≥ 7 ngày / số kích hoạt. Nội dung → cài (hỏi nguồn khi mời hoặc dùng link riêng). CAC bằng giờ = tổng giờ TT (T9–T11) / số kích hoạt. | F20: ĐP | G20: =NGAY_BAT_DAU+70 -> 46349 | H20: =NGAY_BAT_DAU+76 -> 46355 | I20: Chưa bắt đầu | J20: Bảng số có 4 chỉ số
A21: 14 | C21: T11.2 Dòng tiền v0 | D21: Phụ lục C, chỉ phần CHI CỐ ĐỊNH 12 tháng: hạ tầng đám mây (gói hiện tại, ngưỡng miễn phí) · bản đồ (hạn mức tháng) · AI (giá/lượt) · tên miền · phí tài khoản phát hành · phí nộp nhãn hiệu. Ghi giả định; tổng 12 tháng; ai ứng. | F21: ĐP | G21: =NGAY_BAT_DAU+70 -> 46349 | H21: =NGAY_BAT_DAU+76 -> 46355 | I21: Chưa bắt đầu | J21: Sheet v0 + đoạn ghi giả định
A22: 15 | C22: T11.3 4 nội dung còn lại + bảng nội dung | D22: Bảng 10 dòng: nội dung · kênh · ngày · xem 7 ngày · tương tác · cài quy về · học được. | F22: TT | G22: =NGAY_BAT_DAU+70 -> 46349 | H22: =NGAY_BAT_DAU+76 -> 46355 | I22: Chưa bắt đầu | J22: 10 dòng đủ số
A23: 16 | C23: T11.4 Mở rộng bảng đối tác có thể có | D23: Thêm loại: vận chuyển (nhà xe tuyến, thuê xe máy tại tỉnh) · gửi đồ (quán/homestay điểm trung chuyển) · đồ dùng (affiliate sàn) · bảo hiểm (2 hãng bán online). Mỗi loại 2–3 ứng viên + mô hình tiền + giai đoạn. | F23: VH | G23: =NGAY_BAT_DAU+70 -> 46349 | H23: =NGAY_BAT_DAU+76 -> 46355 | I23: Chưa bắt đầu | J23: Bảng ≥ 12 dòng
A24: 17 | C24: T11.5 Chuẩn bị khảo sát «rất thất vọng» | D24: 1 câu bắt buộc (4 lựa chọn) + 3 câu phụ: dùng gì nhiều nhất · thay bằng gì nếu mất · giới thiệu cho ai. Lập form. Danh sách người đủ ≥ 2 tuần dùng (12 người T9 + cohort T10). | F24: SP · ĐP | G24: =NGAY_BAT_DAU+70 -> 46349 | H24: =NGAY_BAT_DAU+76 -> 46355 | I24: Chưa bắt đầu | J24: Form + danh sách người nhận — gửi T12
A25: ="📅 TUẦN 12 · "&TEXT(NGAY_BAT_DAU+77,"dd/mm/yyyy")&" – "&TEXT(NGAY_BAT_DAU+83,"dd/mm/yyyy")&" — CỔNG QUÝ 1 (M12) — tiếp / xoay / dừng │ 🎯 Mục tiêu: Quyết định tiếp / xoay / dừng bằng bảng tiêu chí đã viết trước; chốt Rocks Q2; đủ điều kiện xin phát hành. │ 💡 Cuối tuầ"&"n biết được: Có bằng chứng «khách thật sự cần» hay chưa; nếu xoay thì xoay gì giữ gì; Rocks Q2." -> 📅 TUẦN 12 · 30/11/2026 – 06/12/2026 — CỔNG QUÝ 1 (M12) — tiếp / xoay / dừng │ 🎯 Mục tiêu: Quyết định tiếp / xoay / dừng bằng bảng tiêu chí đã viết trước; chốt Rocks Q2; đủ điều kiện xin phát hành. │ 💡 Cuối tuần biết được: Có bằng chứng «khách thật sự cần» hay chưa; nếu xoay thì xoay gì giữ gì; Rocks Q2.
A26: 18 | B26: QUÝ 1 — GIAI ĐOẠN 1: THẤU CẢM | C26: T12.1 Khảo sát Sean Ellis | D26: Gửi thứ Hai–Tư; nhắc 1 lần; đóng thứ Năm. Tính % «rất thất vọng» trên số người trả lời; ghi rõ tỷ lệ trả lời. Ngưỡng tham chiếu: 40%. | F26: ĐP | G26: =NGAY_BAT_DAU+77 -> 46356 | H26: =NGAY_BAT_DAU+83 -> 46362 | I26: Chưa bắt đầu | J26: Kết quả + cỡ mẫu n
A27: 19 | C27: T12.2 Họp cổng 2 giờ | D27: Bảng tiêu chí giai đoạn 1: mỗi dòng mục tiêu · số thật · đạt/không · bằng chứng. Thảo luận 3 lối ra (Business.md 9.2). Ra ADR. Chốt 3 Rocks Q2 (đề xuất: 100 người hoạt động 1 trường · quay lại 30 ngày ≥ ngưỡng · 3 đối tác thử xong). Cập nhật Phụ lục E. Rà ghế 15'. | F27: ALL | G27: =NGAY_BAT_DAU+77 -> 46356 | H27: =NGAY_BAT_DAU+83 -> 46362 | I27: Chưa bắt đầu | J27: Biên bản cổng Q1 + ADR + Rocks Q2
A28: 20 | C28: T12.3 Điều kiện phát hành production | D28: Kiểm 14 ngày thử kín (T9→T11) đã đủ; 3 việc bắt buộc: báo cáo nội dung · chính sách riêng tư · đường dẫn xoá tài khoản. Nếu đủ thì nộp xin quyền phát hành; chuẩn bị trả lời câu hỏi của Play về thiết kế và quá trình thử nghiệm bằng dữ liệu cohort. | F28: SP · ĐP | G28: =NGAY_BAT_DAU+77 -> 46356 | H28: =NGAY_BAT_DAU+83 -> 46362 | I28: Chưa bắt đầu | J28: Đơn đã nộp, hoặc danh sách còn thiếu có hạn
A29: 21 | C29: T12.4 Cập nhật giai đoạn trong Business.md | D29: Mục 8.6 «Levart hiện ở» → giai đoạn 2 (nếu qua cổng), kèm số. | F29: TN | G29: =NGAY_BAT_DAU+77 -> 46356 | H29: =NGAY_BAT_DAU+83 -> 46362 | I29: Chưa bắt đầu | J29: Tệp cập nhật
A30: ="📅 TUẦN 13 · "&TEXT(NGAY_BAT_DAU+84,"dd/mm/yyyy")&" – "&TEXT(NGAY_BAT_DAU+90,"dd/mm/yyyy")&" — Phỏng vấn người bỏ · Phân loại v2 · Brief con dấu │ 🎯 Mục tiêu: Biết vì sao người ta bỏ; chốt nhãn phân loại; khởi động tài sản hình ảnh; nộp nhãn hiệu. │ 💡 Cuối tuần biết"&" được: 3 lý do bỏ đầu bảng; nhãn phân loại đã chốt; ai thiết kế con dấu; nhãn hiệu đã nộp." -> 📅 TUẦN 13 · 07/12/2026 – 13/12/2026 — Phỏng vấn người bỏ · Phân loại v2 · Brief con dấu │ 🎯 Mục tiêu: Biết vì sao người ta bỏ; chốt nhãn phân loại; khởi động tài sản hình ảnh; nộp nhãn hiệu. │ 💡 Cuối tuần biết được: 3 lý do bỏ đầu bảng; nhãn phân loại đã chốt; ai thiết kế con dấu; nhãn hiệu đã nộp.
A31: 22 | B31: QUÝ 2 — GIAI ĐOẠN 2: BÁM DÍNH | C31: T13.1 5 phỏng vấn người bỏ (churn) | D31: Chọn 5 người đã cài nhưng không mở lại ≥ 7 ngày. 15'/cuộc, gọi hoặc nhắn. Hỏi QUÁ KHỨ: lần cuối mở app làm gì · định làm gì mà không làm được · dùng gì thay · điều gì khiến bạn quay lại app khác. KHÔNG hỏi «nếu có X». Tổng hợp 3 lý do bỏ đầu bảng. | F31: TT | G31: =NGAY_BAT_DAU+84 -> 46363 | H31: =NGAY_BAT_DAU+90 -> 46369 | I31: Chưa bắt đầu | J31: 5 tệp + docs/01_/churn-C2.md — việc quan trọng nhất tuần
A32: 23 | C32: T13.2 Phân loại du lịch v2 | D32: Gộp 40 phỏng vấn (30 + 10); chốt 6–8 nhãn bằng lời khách; định nghĩa 1 dòng/nhãn; đề xuất làm nhãn chuyến đi trong app (SP nhận). | F32: TN | G32: =NGAY_BAT_DAU+84 -> 46363 | H32: =NGAY_BAT_DAU+90 -> 46369 | I32: Chưa bắt đầu | J32: Tệp phân loại v2 + ADR — dùng đo phân khúc nào kích hoạt/quay lại nhiều nhất
A33: 24 | C33: T13.3 Brief tài sản đặc trưng (con dấu 34 tỉnh) | D33: 1–2 trang: mục đích (nhận ra Levart trong 1 giây ở mọi nơi) · yêu cầu: hệ con dấu 34 tỉnh cùng ngôn ngữ hình, 1 màu chủ, 1 hình khoá · dùng ở app, ảnh chia sẻ 9:16, bản in, sticker · tránh giống logo có sẵn · 5 tham chiếu · hạn T16 · đổi công/ghi tên. Tìm người thiết kế (CLB thiết kế, bạn trường mỹ thuật). | F33: TN | G33: =NGAY_BAT_DAU+84 -> 46363 | H33: =NGAY_BAT_DAU+90 -> 46369 | I33: Chưa bắt đầu | J33: Brief + người nhận đã xác nhận
A34: 25 | C34: T13.4 Cập nhật danh mục pháp lý + nộp nhãn hiệu | D34: Nếu tiếp: ước ngày chạm ngưỡng mạng xã hội từ tốc độ tăng cohort → ghi mốc cần pháp nhân. Nộp đơn nhãn hiệu (tự nộp hoặc qua đại diện — hỏi phí); lưu biên nhận. | F34: ĐP | G34: =NGAY_BAT_DAU+84 -> 46363 | H34: =NGAY_BAT_DAU+90 -> 46369 | I34: Chưa bắt đầu | J34: Đơn có số nhận; danh mục pháp lý v1.1
A35: 26 | C35: T13.5 Thu sự cố thật của cohort | D35: Hỏi nhóm chat «chuyến gần nhất gặp chuyện gì?»; ghi vào bảng ngoại lệ, thêm cột «đã xảy ra với người thật». | F35: VH | G35: =NGAY_BAT_DAU+84 -> 46363 | H35: =NGAY_BAT_DAU+90 -> 46369 | I35: Chưa bắt đầu | J35: ≥ 5 sự cố thật trong bảng
A36: ="📅 TUẦN 14 · "&TEXT(NGAY_BAT_DAU+91,"dd/mm/yyyy")&" – "&TEXT(NGAY_BAT_DAU+97,"dd/mm/yyyy")&" — Kết chu kỳ 2 │ 🎯 Mục tiêu: Kết 3 cược bằng số; chọn ≤ 3 tính năng đáng xây và vì sao; chi phí/người v0. │ 💡 Cuối tuần biết được: Cược C2 đúng/sai; 3 tính năng đáng xây và "&"bằng chứng đứng sau; chi phí/người v0." -> 📅 TUẦN 14 · 14/12/2026 – 20/12/2026 — Kết chu kỳ 2 │ 🎯 Mục tiêu: Kết 3 cược bằng số; chọn ≤ 3 tính năng đáng xây và vì sao; chi phí/người v0. │ 💡 Cuối tuần biết được: Cược C2 đúng/sai; 3 tính năng đáng xây và bằng chứng đứng sau; chi phí/người v0.
A37: 27 | B37: QUÝ 2 — GIAI ĐOẠN 2: BÁM DÍNH | C37: T14.1 Kết 3 cược C2 | D37: (A) kích hoạt, quay lại 7 ngày theo kênh so mục tiêu; (B) nội dung → cài; (C) sản phẩm sẵn đúng hạn? Kết luận từng thẻ: tiếp/sửa/bỏ. | F37: ALL | G37: =NGAY_BAT_DAU+91 -> 46370 | H37: =NGAY_BAT_DAU+97 -> 46376 | I37: Chưa bắt đầu | J37: Biên bản kết C2
